Traceback (most recent call last):
  File "/Users/sbello/Documents/personal_repos/2021_machine_learning_and_data_science/.venv/lib/python3.7/site-packages/jupyter_cache/executors/utils.py", line 64, in single_nb_execution
    **kwargs,
  File "/Users/sbello/Documents/personal_repos/2021_machine_learning_and_data_science/.venv/lib/python3.7/site-packages/nbclient/client.py", line 1204, in execute
    return NotebookClient(nb=nb, resources=resources, km=km, **kwargs).execute()
  File "/Users/sbello/Documents/personal_repos/2021_machine_learning_and_data_science/.venv/lib/python3.7/site-packages/nbclient/util.py", line 84, in wrapped
    return just_run(coro(*args, **kwargs))
  File "/Users/sbello/Documents/personal_repos/2021_machine_learning_and_data_science/.venv/lib/python3.7/site-packages/nbclient/util.py", line 62, in just_run
    return loop.run_until_complete(coro)
  File "/Users/sbello/.pyenv/versions/3.7.17/lib/python3.7/asyncio/base_events.py", line 587, in run_until_complete
    return future.result()
  File "/Users/sbello/Documents/personal_repos/2021_machine_learning_and_data_science/.venv/lib/python3.7/site-packages/nbclient/client.py", line 664, in async_execute
    cell, index, execution_count=self.code_cells_executed + 1
  File "/Users/sbello/Documents/personal_repos/2021_machine_learning_and_data_science/.venv/lib/python3.7/site-packages/nbclient/client.py", line 965, in async_execute_cell
    await self._check_raise_for_error(cell, cell_index, exec_reply)
  File "/Users/sbello/Documents/personal_repos/2021_machine_learning_and_data_science/.venv/lib/python3.7/site-packages/nbclient/client.py", line 862, in _check_raise_for_error
    raise CellExecutionError.from_cell_and_msg(cell, exec_reply_content)
nbclient.exceptions.CellExecutionError: An error occurred while executing the following cell:
------------------
nombre = input("Hola. Â¿CÃ³mo te llamas?\n")
------------------

[0;31m---------------------------------------------------------------------------[0m
[0;31mStdinNotImplementedError[0m                  Traceback (most recent call last)
[0;32m/var/folders/k0/k1ptdl95457___jzhps_pq4r8286v9/T/ipykernel_60059/3873998717.py[0m in [0;36m<module>[0;34m[0m
[0;32m----> 1[0;31m [0mnombre[0m [0;34m=[0m [0minput[0m[0;34m([0m[0;34m"Hola. Â¿CÃ³mo te llamas?\n"[0m[0;34m)[0m[0;34m[0m[0;34m[0m[0m
[0m
[0;32m~/Documents/personal_repos/2021_machine_learning_and_data_science/.venv/lib/python3.7/site-packages/ipykernel/kernelbase.py[0m in [0;36mraw_input[0;34m(self, prompt)[0m
[1;32m   1173[0m         [0;32mif[0m [0;32mnot[0m [0mself[0m[0;34m.[0m[0m_allow_stdin[0m[0;34m:[0m[0;34m[0m[0;34m[0m[0m
[1;32m   1174[0m             raise StdinNotImplementedError(
[0;32m-> 1175[0;31m                 [0;34m"raw_input was called, but this frontend does not support input requests."[0m[0;34m[0m[0;34m[0m[0m
[0m[1;32m   1176[0m             )
[1;32m   1177[0m         return self._input_request(

[0;31mStdinNotImplementedError[0m: raw_input was called, but this frontend does not support input requests.
StdinNotImplementedError: raw_input was called, but this frontend does not support input requests.

